<?xml version="1.0"?>
<robot name="my_first_robot" xmlns:xacro="http://www.ros.org/wiki/xacro">
    
    
    <xacro:include filename="$(find my_first_robot)/urdf/my_robot.gazebo"/>

    <link name="base_link" />

    <joint name="base_link_to_chassis" type="fixed">
    <parent link="base_link"/>
    <child link="chassis"/>
    </joint>
    
    <link name="chassis">
        <inertial>
        <mass value="1"/>
        <origin xyz="0.0 0 0.09" rpy=" 0 0 0"/>
        <inertia
            ixx="0.1" ixy="0" ixz="0"
            iyy="0.1" iyz="0"
            izz="0.1"
        />
        </inertial>
        <visual name = 'chassis_visual'>
            <origin xyz="0.0 0 0" rpy=" 0 0 0"/>
            <geometry>
                <box size=" 0.75 0.5 0.17"/>
            </geometry>
        </visual>
        <collision name = 'chassis_collision'>
            <origin xyz="0.0 0 0" rpy=" 0 0 0"/>
            <geometry>
                <box size="0.77 0.52 0.19"/>
            </geometry>
        </collision>
    </link> 

    <link name="right_wheel">
        <visual>
            <geometry>
                <cylinder radius="0.08" length="0.05"/>
            </geometry>
            <origin rpy="1.57075 0.0 0.0" xyz="0.0 0 0"/>
        </visual>
        <collision>
        <origin rpy="1.57075 0.0 0.0" xyz="0.0 0 0"/>
            <geometry>
                <cylinder radius="0.08" length="0.05"/>
            </geometry>
        </collision>

        <inertial>
        <mass value="0.5"/>
        <origin xyz="0.0 0 0" rpy=" 1.5707 0 0"/>
        <inertia
            ixx="0.1" ixy="0" ixz="0"
            iyy="0.1" iyz="0"
            izz="0.1"
        />
        </inertial>
    </link>

    <joint name="chassis_to_right_wheel" type="continuous">
        <origin rpy="0 0.0 0.0" xyz="0.0 -0.275 -0.03"/>
        <parent link="chassis"/>
        <child link="right_wheel"/>
        <axis xyz="0.0 -1 0.0"/>
        <limit  effort="10000" velocity="1000"/>
    </joint>

    <link name="left_wheel">
        <visual>
            <geometry>
                <cylinder radius="0.08" length="0.05"/>
            </geometry>
            <origin rpy="1.57075 0.0 0.0" xyz="0.0 0 0"/>
        </visual>
        <collision>
        <origin rpy="1.57075 0.0 0.0" xyz="0.0 0 0"/>
            <geometry>
                <cylinder radius="0.08" length="0.05"/>
            </geometry>
        </collision>

        <inertial>
        <mass value="0.5"/>
        <origin xyz="0.0 0 0" rpy=" 1.5707 0 0"/>
        <inertia
            ixx="0.1" ixy="0" ixz="0"
            iyy="0.1" iyz="0"
            izz="0.1"
        />
        </inertial>
    </link>

    <joint name="chassis_to_left_wheel" type="continuous">
        <origin rpy="0 0.0 0.0" xyz="0.0 0.275 -0.03"/>
        <parent link="chassis"/>
        <child link="left_wheel"/>
        <axis xyz="0 1 0.0"/>
        <limit  effort="10000" velocity="1000"/>
    </joint>

    <link name="lidar">
        <visual>
            <geometry>
                <box size="0.05 0.05 0.05"/>
            </geometry>
            <origin rpy="0.0 0.0 0.0" xyz="0.0 0 0"/>
        </visual>
        <collision>
        <origin rpy="0.0 0.0 0.0" xyz="0.0 0 0"/>
            <geometry>
                <box size="0.05 0.05 0.05"/>
            </geometry>
        </collision>

        <inertial>
        <mass value="0.2"/>
        <origin xyz="0.0 0 0" rpy=" 0 0 0"/>
        <inertia
            ixx="0.1" ixy="0" ixz="0"
            iyy="0.1" iyz="0"
            izz="0.1"
        />
        </inertial>
    </link>
    
    <joint name="chassis_to_lidar" type="fixed">
        <origin rpy="0 0.0 0.0" xyz="0.33 0.0 0.09"/>
        <parent link="chassis"/>
        <child link="lidar"/>
    </joint>

    <link name="camera">
        <visual>
            <geometry>
                <box size="0.04 0.1 .06"/>
            </geometry>
            <origin rpy="0.0 0.0 0.0" xyz="0.0 0 0"/>
        </visual>
        <collision>
        <origin rpy="0.0 0.0 0.0" xyz="0.0 0 0"/>
            <geometry>
                <box size="0.04 0.1 0.06"/>
            </geometry>
        </collision>

        <inertial>
        <mass value="0.1"/>
        <origin xyz="0.0 0 0" rpy=" 0 0 0"/>
        <inertia
            ixx="0.1" ixy="0" ixz="0"
            iyy="0.1" iyz="0"
            izz="0.1"
        />
        </inertial>
    </link>
    
    <joint name="camera_to_lidar" type="fixed">
        <origin rpy="0 0.0 0.0" xyz="0.395 0.0 0"/>
        <parent link="chassis"/>
        <child link="camera"/>
    </joint>

</robot>
